<?xml version="1.0" ?>
<!-- =================================================================================== -->
<!-- |    This document was autogenerated by xacro from /home/mglhbr/ros2_ws/src/icarus_URDF_stack/icarus_orca_description/urdf/icarus_orca.urdf | -->
<!-- |    EDITING THIS FILE BY HAND IS NOT RECOMMENDED                                 | -->
<!-- =================================================================================== -->
<robot name="icarus_orca">
  <link name="world"/>
  <joint name="world_to_base" type="fixed">
    <parent link="world"/>
    <child link="base_link"/>
    <origin rpy="0 0 0" xyz="0 0 0"/>
  </joint>
  <!-- Shared material definitions -->
  <material name="white">
    <color rgba="1 1 1 1"/>
  </material>
  <material name="silver">
    <color rgba="0.700 0.700 0.700 1.000"/>
  </material>
  <material name="black">
    <color rgba="0.15 0.15 0.15 1.000"/>
  </material>
  <transmission name="Revolute 1_tran">
    <type>transmission_interface/SimpleTransmission</type>
    <joint name="Revolute 1">
      <hardwareInterface>hardware_interface/EffortJointInterface</hardwareInterface>
    </joint>
    <actuator name="Revolute 1_actr">
      <hardwareInterface>hardware_interface/EffortJointInterface</hardwareInterface>
      <mechanicalReduction>1</mechanicalReduction>
    </actuator>
  </transmission>
  <transmission name="Revolute 3_tran">
    <type>transmission_interface/SimpleTransmission</type>
    <joint name="Revolute 3">
      <hardwareInterface>hardware_interface/EffortJointInterface</hardwareInterface>
    </joint>
    <actuator name="Revolute 3_actr">
      <hardwareInterface>hardware_interface/EffortJointInterface</hardwareInterface>
      <mechanicalReduction>1</mechanicalReduction>
    </actuator>
  </transmission>
  <transmission name="Revolute 9_tran">
    <type>transmission_interface/SimpleTransmission</type>
    <joint name="Revolute 9">
      <hardwareInterface>hardware_interface/EffortJointInterface</hardwareInterface>
    </joint>
    <actuator name="Revolute 9_actr">
      <hardwareInterface>hardware_interface/EffortJointInterface</hardwareInterface>
      <mechanicalReduction>1</mechanicalReduction>
    </actuator>
  </transmission>
  <transmission name="Revolute 20_tran">
    <type>transmission_interface/SimpleTransmission</type>
    <joint name="Revolute 20">
      <hardwareInterface>hardware_interface/EffortJointInterface</hardwareInterface>
    </joint>
    <actuator name="Revolute 20_actr">
      <hardwareInterface>hardware_interface/EffortJointInterface</hardwareInterface>
      <mechanicalReduction>1</mechanicalReduction>
    </actuator>
  </transmission>
  <transmission name="Revolute 26_tran">
    <type>transmission_interface/SimpleTransmission</type>
    <joint name="Revolute 26">
      <hardwareInterface>hardware_interface/EffortJointInterface</hardwareInterface>
    </joint>
    <actuator name="Revolute 26_actr">
      <hardwareInterface>hardware_interface/EffortJointInterface</hardwareInterface>
      <mechanicalReduction>1</mechanicalReduction>
    </actuator>
  </transmission>
  <gazebo>
    <plugin filename="libgazebo_ros_control.so" name="control"/>
  </gazebo>
  <gazebo reference="base_link">
    <material>Gazebo/Silver</material>
    <mu1>0.2</mu1>
    <mu2>0.2</mu2>
    <selfCollide>true</selfCollide>
    <gravity>true</gravity>
  </gazebo>
  <gazebo reference="connector_link2_1">
    <material>Gazebo/Silver</material>
    <mu1>0.2</mu1>
    <mu2>0.2</mu2>
    <selfCollide>true</selfCollide>
  </gazebo>
  <gazebo reference="motor2_link3_1">
    <material>Gazebo/Silver</material>
    <mu1>0.2</mu1>
    <mu2>0.2</mu2>
    <selfCollide>true</selfCollide>
  </gazebo>
  <gazebo reference="uaconnector_link4_1">
    <material>Gazebo/Silver</material>
    <mu1>0.2</mu1>
    <mu2>0.2</mu2>
    <selfCollide>true</selfCollide>
  </gazebo>
  <gazebo reference="case_link5_1">
    <material>Gazebo/Silver</material>
    <mu1>0.2</mu1>
    <mu2>0.2</mu2>
    <selfCollide>true</selfCollide>
  </gazebo>
  <gazebo reference="motor3_link6_1">
    <material>Gazebo/Silver</material>
    <mu1>0.2</mu1>
    <mu2>0.2</mu2>
    <selfCollide>true</selfCollide>
  </gazebo>
  <gazebo reference="slot_link7_1">
    <material>Gazebo/Silver</material>
    <mu1>0.2</mu1>
    <mu2>0.2</mu2>
    <selfCollide>true</selfCollide>
  </gazebo>
  <gazebo reference="baringattacher_link8_1">
    <material>Gazebo/Silver</material>
    <mu1>0.2</mu1>
    <mu2>0.2</mu2>
    <selfCollide>true</selfCollide>
  </gazebo>
  <gazebo reference="bearingouter_link10_1">
    <material>Gazebo/Silver</material>
    <mu1>0.2</mu1>
    <mu2>0.2</mu2>
    <selfCollide>true</selfCollide>
  </gazebo>
  <gazebo reference="bearinginner_link9_1">
    <material>Gazebo/Silver</material>
    <mu1>0.2</mu1>
    <mu2>0.2</mu2>
    <selfCollide>true</selfCollide>
  </gazebo>
  <gazebo reference="frame1_link11_1">
    <material>Gazebo/Silver</material>
    <mu1>0.2</mu1>
    <mu2>0.2</mu2>
    <selfCollide>true</selfCollide>
  </gazebo>
  <gazebo reference="frame2_link12_1">
    <material>Gazebo/Silver</material>
    <mu1>0.2</mu1>
    <mu2>0.2</mu2>
    <selfCollide>true</selfCollide>
  </gazebo>
  <gazebo reference="motor4_link13_1">
    <material>Gazebo/Silver</material>
    <mu1>0.2</mu1>
    <mu2>0.2</mu2>
    <selfCollide>true</selfCollide>
  </gazebo>
  <gazebo reference="bearingleft_link16_1">
    <material>Gazebo/Silver</material>
    <mu1>0.2</mu1>
    <mu2>0.2</mu2>
    <selfCollide>true</selfCollide>
  </gazebo>
  <gazebo reference="motor5_link17_1">
    <material>Gazebo/Silver</material>
    <mu1>0.2</mu1>
    <mu2>0.2</mu2>
    <selfCollide>true</selfCollide>
  </gazebo>
  <gazebo reference="outerbearing_link18_1">
    <material>Gazebo/Silver</material>
    <mu1>0.2</mu1>
    <mu2>0.2</mu2>
    <selfCollide>true</selfCollide>
  </gazebo>
  <gazebo reference="bearingright_link14_1">
    <material>Gazebo/Silver</material>
    <mu1>0.2</mu1>
    <mu2>0.2</mu2>
    <selfCollide>true</selfCollide>
  </gazebo>
  <gazebo reference="elbowconnector_link15_1">
    <material>Gazebo/Silver</material>
    <mu1>0.2</mu1>
    <mu2>0.2</mu2>
    <selfCollide>true</selfCollide>
  </gazebo>
  <gazebo reference="innerbearing_link20_1">
    <material>Gazebo/Silver</material>
    <mu1>0.2</mu1>
    <mu2>0.2</mu2>
    <selfCollide>true</selfCollide>
  </gazebo>
  <gazebo reference="handconnector_link21_1">
    <material>Gazebo/Silver</material>
    <mu1>0.2</mu1>
    <mu2>0.2</mu2>
    <selfCollide>true</selfCollide>
  </gazebo>
  <link name="base_link">
    <inertial>
      <origin rpy="0 0 0" xyz="0.0023603151773317708 0.11012151831905279 0.01659072255258487"/>
      <mass value="2.73842616957922"/>
      <inertia ixx="0.002101" ixy="3e-06" ixz="0.0" iyy="0.003104" iyz="-3e-06" izz="0.002104"/>
    </inertial>
    <visual>
      <origin rpy="0 0 0" xyz="0 0 0"/>
      <geometry>
        <mesh filename="package://icarus_urdf_v2_copy_description/meshes/base_link.stl" scale="0.001 0.001 0.001"/>
      </geometry>
      <material name="silver"/>
    </visual>
    <collision>
      <origin rpy="0 0 0" xyz="0 0 0"/>
      <geometry>
        <mesh filename="package://icarus_urdf_v2_copy_description/meshes/base_link.stl" scale="0.001 0.001 0.001"/>
      </geometry>
    </collision>
  </link>
  <link name="connector_link2_1">
    <inertial>
      <origin rpy="0 0 0" xyz="1.2655616561663141e-08 -0.030526814766274522 -7.263566383780562e-09"/>
      <mass value="0.10495230755525947"/>
      <inertia ixx="0.000174" ixy="0.0" ixz="-0.0" iyy="0.000121" iyz="-0.0" izz="0.00015"/>
    </inertial>
    <visual>
      <origin rpy="0 0 0" xyz="-0.0024 -0.082479 -0.01655"/>
      <geometry>
        <mesh filename="package://icarus_urdf_v2_copy_description/meshes/connector_link2_1.stl" scale="0.001 0.001 0.001"/>
      </geometry>
      <material name="black"/>
    </visual>
    <collision>
      <origin rpy="0 0 0" xyz="-0.0024 -0.082479 -0.01655"/>
      <geometry>
        <mesh filename="package://icarus_urdf_v2_copy_description/meshes/connector_link2_1.stl" scale="0.001 0.001 0.001"/>
      </geometry>
    </collision>
  </link>
  <link name="motor2_link3_1">
    <inertial>
      <origin rpy="0 0 0" xyz="-0.01894251066244622 -3.9678016027743825e-05 4.0722999287274436e-05"/>
      <mass value="2.738426169579209"/>
      <inertia ixx="0.003104" ixy="-3e-06" ixz="3e-06" iyy="0.002101" iyz="0.0" izz="0.002104"/>
    </inertial>
    <visual>
      <origin rpy="0 0 0" xyz="-0.0228 0.004521 -0.01655"/>
      <geometry>
        <mesh filename="package://icarus_urdf_v2_copy_description/meshes/motor2_link3_1.stl" scale="0.001 0.001 0.001"/>
      </geometry>
      <material name="silver"/>
    </visual>
    <collision>
      <origin rpy="0 0 0" xyz="-0.0228 0.004521 -0.01655"/>
      <geometry>
        <mesh filename="package://icarus_urdf_v2_copy_description/meshes/motor2_link3_1.stl" scale="0.001 0.001 0.001"/>
      </geometry>
    </collision>
  </link>
  <link name="uaconnector_link4_1">
    <inertial>
      <origin rpy="0 0 0" xyz="0.0020433896815537506 2.237721405342133e-06 -0.03694485555361714"/>
      <mass value="0.10373809287746867"/>
      <inertia ixx="0.00015" ixy="-0.0" ixz="-3.5e-05" iyy="0.000176" iyz="-0.0" izz="0.000119"/>
    </inertial>
    <visual>
      <origin rpy="0 0 0" xyz="-0.0315 0.004521 -0.01655"/>
      <geometry>
        <mesh filename="package://icarus_urdf_v2_copy_description/meshes/uaconnector_link4_1.stl" scale="0.001 0.001 0.001"/>
      </geometry>
      <material name="black"/>
    </visual>
    <collision>
      <origin rpy="0 0 0" xyz="-0.0315 0.004521 -0.01655"/>
      <geometry>
        <mesh filename="package://icarus_urdf_v2_copy_description/meshes/uaconnector_link4_1.stl" scale="0.001 0.001 0.001"/>
      </geometry>
    </collision>
  </link>
  <link name="case_link5_1">
    <inertial>
      <origin rpy="0 0 0" xyz="0.0032116723577653257 4.745850763591963e-09 -0.045553126635455354"/>
      <mass value="0.10350251099857245"/>
      <inertia ixx="0.000169" ixy="0.0" ixz="1.5e-05" iyy="0.000164" iyz="-0.0" izz="0.00014"/>
    </inertial>
    <visual>
      <origin rpy="0 0 0" xyz="-0.0 0.004521 0.05545"/>
      <geometry>
        <mesh filename="package://icarus_urdf_v2_copy_description/meshes/case_link5_1.stl" scale="0.001 0.001 0.001"/>
      </geometry>
      <material name="black"/>
    </visual>
    <collision>
      <origin rpy="0 0 0" xyz="-0.0 0.004521 0.05545"/>
      <geometry>
        <mesh filename="package://icarus_urdf_v2_copy_description/meshes/case_link5_1.stl" scale="0.001 0.001 0.001"/>
      </geometry>
    </collision>
  </link>
  <link name="motor3_link6_1">
    <inertial>
      <origin rpy="0 0 0" xyz="-0.00010596699919717758 -9.560232229104473e-07 0.02493920389115259"/>
      <mass value="0.9769498564987956"/>
      <inertia ixx="0.000405" ixy="-0.0" ixz="3e-06" iyy="0.000407" iyz="0.0" izz="0.000401"/>
    </inertial>
    <visual>
      <origin rpy="0 0 0" xyz="-0.0 0.004521 0.125"/>
      <geometry>
        <mesh filename="package://icarus_urdf_v2_copy_description/meshes/motor3_link6_1.stl" scale="0.001 0.001 0.001"/>
      </geometry>
      <material name="silver"/>
    </visual>
    <collision>
      <origin rpy="0 0 0" xyz="-0.0 0.004521 0.125"/>
      <geometry>
        <mesh filename="package://icarus_urdf_v2_copy_description/meshes/motor3_link6_1.stl" scale="0.001 0.001 0.001"/>
      </geometry>
    </collision>
  </link>
  <link name="slot_link7_1">
    <inertial>
      <origin rpy="0 0 0" xyz="-0.032637651502962516 6.807233410635605e-09 -0.011691879876810918"/>
      <mass value="0.01067094946660519"/>
      <inertia ixx="7e-06" ixy="-0.0" ixz="0.0" iyy="1e-06" iyz="-0.0" izz="8e-06"/>
    </inertial>
    <visual>
      <origin rpy="0 0 0" xyz="-0.0 0.004521 0.1325"/>
      <geometry>
        <mesh filename="package://icarus_urdf_v2_copy_description/meshes/slot_link7_1.stl" scale="0.001 0.001 0.001"/>
      </geometry>
      <material name="black"/>
    </visual>
    <collision>
      <origin rpy="0 0 0" xyz="-0.0 0.004521 0.1325"/>
      <geometry>
        <mesh filename="package://icarus_urdf_v2_copy_description/meshes/slot_link7_1.stl" scale="0.001 0.001 0.001"/>
      </geometry>
    </collision>
  </link>
  <link name="baringattacher_link8_1">
    <inertial>
      <origin rpy="0 0 0" xyz="-1.739764543349103e-09 9.82781693708093e-08 0.009727183658919614"/>
      <mass value="0.01613078980443655"/>
      <inertia ixx="3e-06" ixy="0.0" ixz="-0.0" iyy="3e-06" iyz="0.0" izz="5e-06"/>
    </inertial>
    <visual>
      <origin rpy="0 0 0" xyz="-0.0 0.004521 0.155"/>
      <geometry>
        <mesh filename="package://icarus_urdf_v2_copy_description/meshes/baringattacher_link8_1.stl" scale="0.001 0.001 0.001"/>
      </geometry>
      <material name="black"/>
    </visual>
    <collision>
      <origin rpy="0 0 0" xyz="-0.0 0.004521 0.155"/>
      <geometry>
        <mesh filename="package://icarus_urdf_v2_copy_description/meshes/baringattacher_link8_1.stl" scale="0.001 0.001 0.001"/>
      </geometry>
    </collision>
  </link>
  <link name="bearingouter_link10_1">
    <inertial>
      <origin rpy="0 0 0" xyz="1.3500311979441904e-15 6.80723428146679e-09 -0.0076296301443288805"/>
      <mass value="0.3881951668433359"/>
      <inertia ixx="0.000335" ixy="-0.0" ixz="-0.0" iyy="0.000335" iyz="0.0" izz="0.000657"/>
    </inertial>
    <visual>
      <origin rpy="0 0 0" xyz="-0.0 0.004521 0.155"/>
      <geometry>
        <mesh filename="package://icarus_urdf_v2_copy_description/meshes/bearingouter_link10_1.stl" scale="0.001 0.001 0.001"/>
      </geometry>
      <material name="silver"/>
    </visual>
    <collision>
      <origin rpy="0 0 0" xyz="-0.0 0.004521 0.155"/>
      <geometry>
        <mesh filename="package://icarus_urdf_v2_copy_description/meshes/bearingouter_link10_1.stl" scale="0.001 0.001 0.001"/>
      </geometry>
    </collision>
  </link>
  <link name="bearinginner_link9_1">
    <inertial>
      <origin rpy="0 0 0" xyz="6.750155989720952e-16 6.807232913637329e-09 0.0065000000000001446"/>
      <mass value="0.27223986557227087"/>
      <inertia ixx="0.0001" ixy="-0.0" ixz="-0.0" iyy="0.0001" iyz="-0.0" izz="0.000191"/>
    </inertial>
    <visual>
      <origin rpy="0 0 0" xyz="-0.0 0.004521 0.169"/>
      <geometry>
        <mesh filename="package://icarus_urdf_v2_copy_description/meshes/bearinginner_link9_1.stl" scale="0.001 0.001 0.001"/>
      </geometry>
      <material name="silver"/>
    </visual>
    <collision>
      <origin rpy="0 0 0" xyz="-0.0 0.004521 0.169"/>
      <geometry>
        <mesh filename="package://icarus_urdf_v2_copy_description/meshes/bearinginner_link9_1.stl" scale="0.001 0.001 0.001"/>
      </geometry>
    </collision>
  </link>
  <link name="frame1_link11_1">
    <inertial>
      <origin rpy="0 0 0" xyz="-0.014789956482355341 -0.009932221222018513 -0.07235344508044969"/>
      <mass value="0.17567366682185703"/>
      <inertia ixx="0.000428" ixy="3e-06" ixz="-6.1e-05" iyy="0.000436" iyz="-2e-05" izz="0.000163"/>
    </inertial>
    <visual>
      <origin rpy="0 0 0" xyz="-0.0 0.004521 0.17"/>
      <geometry>
        <mesh filename="package://icarus_urdf_v2_copy_description/meshes/frame1_link11_1.stl" scale="0.001 0.001 0.001"/>
      </geometry>
      <material name="black"/>
    </visual>
    <collision>
      <origin rpy="0 0 0" xyz="-0.0 0.004521 0.17"/>
      <geometry>
        <mesh filename="package://icarus_urdf_v2_copy_description/meshes/frame1_link11_1.stl" scale="0.001 0.001 0.001"/>
      </geometry>
    </collision>
  </link>
  <link name="frame2_link12_1">
    <inertial>
      <origin rpy="0 0 0" xyz="-0.12522967410092206 -0.0010753534023040315 0.011933230796448563"/>
      <mass value="0.06832532468162396"/>
      <inertia ixx="0.000144" ixy="-5e-06" ixz="-1.8e-05" iyy="0.000171" iyz="-2e-06" izz="3.9e-05"/>
    </inertial>
    <visual>
      <origin rpy="0 0 0" xyz="-0.112386 -0.027458 0.259767"/>
      <geometry>
        <mesh filename="package://icarus_urdf_v2_copy_description/meshes/frame2_link12_1.stl" scale="0.001 0.001 0.001"/>
      </geometry>
      <material name="black"/>
    </visual>
    <collision>
      <origin rpy="0 0 0" xyz="-0.112386 -0.027458 0.259767"/>
      <geometry>
        <mesh filename="package://icarus_urdf_v2_copy_description/meshes/frame2_link12_1.stl" scale="0.001 0.001 0.001"/>
      </geometry>
    </collision>
  </link>
  <link name="motor4_link13_1">
    <inertial>
      <origin rpy="0 0 0" xyz="-0.00010596895863974403 0.024939207526008297 9.599493267509196e-07"/>
      <mass value="0.9769498564987962"/>
      <inertia ixx="0.000405" ixy="3e-06" ixz="0.0" iyy="0.000401" iyz="-0.0" izz="0.000407"/>
    </inertial>
    <visual>
      <origin rpy="0 0 0" xyz="0.0 0.034021 0.2085"/>
      <geometry>
        <mesh filename="package://icarus_urdf_v2_copy_description/meshes/motor4_link13_1.stl" scale="0.001 0.001 0.001"/>
      </geometry>
      <material name="silver"/>
    </visual>
    <collision>
      <origin rpy="0 0 0" xyz="0.0 0.034021 0.2085"/>
      <geometry>
        <mesh filename="package://icarus_urdf_v2_copy_description/meshes/motor4_link13_1.stl" scale="0.001 0.001 0.001"/>
      </geometry>
    </collision>
  </link>
  <link name="bearingleft_link16_1">
    <inertial>
      <origin rpy="0 0 0" xyz="-2.6871912794622145e-16 -0.003499986385532672 1.1102230246251565e-16"/>
      <mass value="0.027522236601038728"/>
      <inertia ixx="4e-06" ixy="0.0" ixz="0.0" iyy="7e-06" iyz="0.0" izz="4e-06"/>
    </inertial>
    <visual>
      <origin rpy="0 0 0" xyz="0.0 -0.034458 0.33"/>
      <geometry>
        <mesh filename="package://icarus_urdf_v2_copy_description/meshes/bearingleft_link16_1.stl" scale="0.001 0.001 0.001"/>
      </geometry>
      <material name="silver"/>
    </visual>
    <collision>
      <origin rpy="0 0 0" xyz="0.0 -0.034458 0.33"/>
      <geometry>
        <mesh filename="package://icarus_urdf_v2_copy_description/meshes/bearingleft_link16_1.stl" scale="0.001 0.001 0.001"/>
      </geometry>
    </collision>
  </link>
  <link name="motor5_link17_1">
    <inertial>
      <origin rpy="0 0 0" xyz="-9.555639901448032e-05 9.585296300926218e-05 0.02025906960996804"/>
      <mass value="0.7753717946682805"/>
      <inertia ixx="0.000267" ixy="1e-06" ixz="2e-06" iyy="0.000267" iyz="-2e-06" izz="0.00032"/>
    </inertial>
    <visual>
      <origin rpy="0 0 0" xyz="0.0 0.004521 0.36"/>
      <geometry>
        <mesh filename="package://icarus_urdf_v2_copy_description/meshes/motor5_link17_1.stl" scale="0.001 0.001 0.001"/>
      </geometry>
      <material name="silver"/>
    </visual>
    <collision>
      <origin rpy="0 0 0" xyz="0.0 0.004521 0.36"/>
      <geometry>
        <mesh filename="package://icarus_urdf_v2_copy_description/meshes/motor5_link17_1.stl" scale="0.001 0.001 0.001"/>
      </geometry>
    </collision>
  </link>
  <link name="outerbearing_link18_1">
    <inertial>
      <origin rpy="0 0 0" xyz="-3.3017278275184507e-16 6.8072340039110335e-09 -0.007370369855673242"/>
      <mass value="0.38819516684333627"/>
      <inertia ixx="0.000335" ixy="-0.0" ixz="0.0" iyy="0.000335" iyz="-0.0" izz="0.000657"/>
    </inertial>
    <visual>
      <origin rpy="0 0 0" xyz="0.0 0.004521 0.381"/>
      <geometry>
        <mesh filename="package://icarus_urdf_v2_copy_description/meshes/outerbearing_link18_1.stl" scale="0.001 0.001 0.001"/>
      </geometry>
      <material name="silver"/>
    </visual>
    <collision>
      <origin rpy="0 0 0" xyz="0.0 0.004521 0.381"/>
      <geometry>
        <mesh filename="package://icarus_urdf_v2_copy_description/meshes/outerbearing_link18_1.stl" scale="0.001 0.001 0.001"/>
      </geometry>
    </collision>
  </link>
  <link name="bearingright_link14_1">
    <inertial>
      <origin rpy="0 0 0" xyz="-1.934114156344474e-16 -0.003499999999999899 0.0"/>
      <mass value="0.027522236601038728"/>
      <inertia ixx="4e-06" ixy="0.0" ixz="0.0" iyy="7e-06" iyz="0.0" izz="4e-06"/>
    </inertial>
    <visual>
      <origin rpy="0 0 0" xyz="0.0 0.0365 0.33"/>
      <geometry>
        <mesh filename="package://icarus_urdf_v2_copy_description/meshes/bearingright_link14_1.stl" scale="0.001 0.001 0.001"/>
      </geometry>
      <material name="silver"/>
    </visual>
    <collision>
      <origin rpy="0 0 0" xyz="0.0 0.0365 0.33"/>
      <geometry>
        <mesh filename="package://icarus_urdf_v2_copy_description/meshes/bearingright_link14_1.stl" scale="0.001 0.001 0.001"/>
      </geometry>
    </collision>
  </link>
  <link name="elbowconnector_link15_1">
    <inertial>
      <origin rpy="0 0 0" xyz="-5.4575951964102475e-05 0.039403848113256715 -0.02494620164496325"/>
      <mass value="0.05903950761890433"/>
      <inertia ixx="5.8e-05" ixy="0.0" ixz="0.0" iyy="5.9e-05" iyz="-1e-06" izz="7.9e-05"/>
    </inertial>
    <visual>
      <origin rpy="0 0 0" xyz="0.0 0.0435 0.33"/>
      <geometry>
        <mesh filename="package://icarus_urdf_v2_copy_description/meshes/elbowconnector_link15_1.stl" scale="0.001 0.001 0.001"/>
      </geometry>
      <material name="black"/>
    </visual>
    <collision>
      <origin rpy="0 0 0" xyz="0.0 0.0435 0.33"/>
      <geometry>
        <mesh filename="package://icarus_urdf_v2_copy_description/meshes/elbowconnector_link15_1.stl" scale="0.001 0.001 0.001"/>
      </geometry>
    </collision>
  </link>
  <link name="innerbearing_link20_1">
    <inertial>
      <origin rpy="0 0 0" xyz="-3.283474033666947e-16 6.807233978757543e-09 0.00649999999999773"/>
      <mass value="0.27223986557227076"/>
      <inertia ixx="0.0001" ixy="-0.0" ixz="0.0" iyy="0.0001" iyz="-0.0" izz="0.000191"/>
    </inertial>
    <visual>
      <origin rpy="0 0 0" xyz="0.0 0.004521 0.395"/>
      <geometry>
        <mesh filename="package://icarus_urdf_v2_copy_description/meshes/innerbearing_link20_1.stl" scale="0.001 0.001 0.001"/>
      </geometry>
      <material name="silver"/>
    </visual>
    <collision>
      <origin rpy="0 0 0" xyz="0.0 0.004521 0.395"/>
      <geometry>
        <mesh filename="package://icarus_urdf_v2_copy_description/meshes/innerbearing_link20_1.stl" scale="0.001 0.001 0.001"/>
      </geometry>
    </collision>
  </link>
  <link name="handconnector_link21_1">
    <inertial>
      <origin rpy="0 0 0" xyz="-5.069506950090064e-06 2.2418951324890135e-07 -0.013822457486656448"/>
      <mass value="0.06934651168813202"/>
      <inertia ixx="5.3e-05" ixy="0.0" ixz="-0.0" iyy="5.8e-05" iyz="0.0" izz="5.6e-05"/>
    </inertial>
    <visual>
      <origin rpy="0 0 0" xyz="0.0 0.004521 0.396"/>
      <geometry>
        <mesh filename="package://icarus_urdf_v2_copy_description/meshes/handconnector_link21_1.stl" scale="0.001 0.001 0.001"/>
      </geometry>
      <material name="black"/>
    </visual>
    <collision>
      <origin rpy="0 0 0" xyz="0.0 0.004521 0.396"/>
      <geometry>
        <mesh filename="package://icarus_urdf_v2_copy_description/meshes/handconnector_link21_1.stl" scale="0.001 0.001 0.001"/>
      </geometry>
    </collision>
  </link>
  <joint name="Revolute 1" type="continuous">
    <origin rpy="0 0 0" xyz="0.0024 0.082479 0.01655"/>
    <parent link="base_link"/>
    <child link="connector_link2_1"/>
    <axis xyz="0.0 1.0 0.0"/>
  </joint>
  <joint name="Rigid 2" type="fixed">
    <origin rpy="0 0 0" xyz="0.0204 -0.087 0.0"/>
    <parent link="connector_link2_1"/>
    <child link="motor2_link3_1"/>
  </joint>
  <joint name="Revolute 3" type="revolute">
    <origin rpy="0 0 0" xyz="0.0087 0.0 0.0"/>
    <parent link="motor2_link3_1"/>
    <child link="uaconnector_link4_1"/>
    <axis xyz="-1.0 -0.0 0.0"/>
    <limit effort="100" lower="-0.261799" upper="3.403392" velocity="100"/>
  </joint>
  <joint name="Rigid 4" type="fixed">
    <origin rpy="0 0 0" xyz="-0.0315 0.0 -0.072"/>
    <parent link="uaconnector_link4_1"/>
    <child link="case_link5_1"/>
  </joint>
  <joint name="Rigid 5" type="fixed">
    <origin rpy="0 0 0" xyz="0.0 0.0 -0.06955"/>
    <parent link="case_link5_1"/>
    <child link="motor3_link6_1"/>
  </joint>
  <joint name="Rigid 6" type="fixed">
    <origin rpy="0 0 0" xyz="0.0 0.0 -0.07705"/>
    <parent link="case_link5_1"/>
    <child link="slot_link7_1"/>
  </joint>
  <joint name="Rigid 7" type="fixed">
    <origin rpy="0 0 0" xyz="0.0 0.0 0.014"/>
    <parent link="bearinginner_link9_1"/>
    <child link="baringattacher_link8_1"/>
  </joint>
  <joint name="Rigid 8" type="fixed">
    <origin rpy="0 0 0" xyz="0.0 0.0 -0.09955"/>
    <parent link="case_link5_1"/>
    <child link="bearingouter_link10_1"/>
  </joint>
  <joint name="Revolute 9" type="continuous">
    <origin rpy="0 0 0" xyz="0.0 0.0 -0.014"/>
    <parent link="bearingouter_link10_1"/>
    <child link="bearinginner_link9_1"/>
    <axis xyz="0.0 -0.0 1.0"/>
  </joint>
  <joint name="Rigid 10" type="fixed">
    <origin rpy="0 0 0" xyz="0.0 0.0 -0.001"/>
    <parent link="bearinginner_link9_1"/>
    <child link="frame1_link11_1"/>
  </joint>
  <joint name="Rigid 11" type="fixed">
    <origin rpy="0 0 0" xyz="0.112386 0.031979 -0.089767"/>
    <parent link="frame1_link11_1"/>
    <child link="frame2_link12_1"/>
  </joint>
  <joint name="Rigid 12" type="fixed">
    <origin rpy="0 0 0" xyz="-0.0 -0.0295 -0.0385"/>
    <parent link="frame1_link11_1"/>
    <child link="motor4_link13_1"/>
  </joint>
  <joint name="Rigid 14" type="fixed">
    <origin rpy="0 0 0" xyz="0.0 0.077958 0.0"/>
    <parent link="elbowconnector_link15_1"/>
    <child link="bearingleft_link16_1"/>
  </joint>
  <joint name="Rigid 15" type="fixed">
    <origin rpy="0 0 0" xyz="0.0 0.038979 -0.03"/>
    <parent link="elbowconnector_link15_1"/>
    <child link="motor5_link17_1"/>
  </joint>
  <joint name="Rigid 16" type="fixed">
    <origin rpy="0 0 0" xyz="0.0 0.038979 -0.051"/>
    <parent link="elbowconnector_link15_1"/>
    <child link="outerbearing_link18_1"/>
  </joint>
  <joint name="Revolute 20" type="revolute">
    <origin rpy="0 0 0" xyz="-0.0 -0.031979 -0.16"/>
    <parent link="frame1_link11_1"/>
    <child link="bearingright_link14_1"/>
    <axis xyz="0.0 1.0 0.0"/>
    <limit effort="100" lower="-2.356194" upper="0.610865" velocity="100"/>
  </joint>
  <joint name="Rigid 21" type="fixed">
    <origin rpy="0 0 0" xyz="0.0 -0.007 0.0"/>
    <parent link="bearingright_link14_1"/>
    <child link="elbowconnector_link15_1"/>
  </joint>
  <joint name="Revolute 26" type="continuous">
    <origin rpy="0 0 0" xyz="0.0 0.0 -0.014"/>
    <parent link="outerbearing_link18_1"/>
    <child link="innerbearing_link20_1"/>
    <axis xyz="0.0 0.0 1.0"/>
  </joint>
  <joint name="Rigid 27" type="fixed">
    <origin rpy="0 0 0" xyz="0.0 0.0 -0.001"/>
    <parent link="innerbearing_link20_1"/>
    <child link="handconnector_link21_1"/>
  </joint>
  <link name="right_tower">
    <inertial>
      <origin rpy="-0.0026099999999999977 0.007370000000000099 0.04145" xyz="0.04034 -0.00091 0.01912"/>
      <mass value="0.9"/>
      <inertia ixx="0.00150422" ixy="0" ixz="0" iyy="0.00125262" iyz="0" izz="0.0007962"/>
    </inertial>
    <visual name="right_visual_tower_main_mesh">
      <origin rpy="-0.007252153364137093 -0.004356332895580239 1.533990149039079" xyz="0.04069509610470536 -0.00012511806280993186 0.02312294830988657"/>
      <geometry>
        <mesh filename="package://orcahand_description/assets/urdf/right/visual/right_visual_tower_main_mesh.stl"/>
      </geometry>
      <material name="white"/>
    </visual>
    <collision name="right_collision_tower_main_mesh">
      <origin rpy="0.0663641604020242 -0.10532695421927696 -0.7765909134463538" xyz="0.041026105966065735 0.0008755408110132971 0.03758955025925282"/>
      <geometry>
        <mesh filename="package://orcahand_description/assets/urdf/right/collision/right_collision_tower_main_mesh.stl"/>
      </geometry>
      <material name="white"/>
    </collision>
    <visual name="right_visual_tower_hull_mesh">
      <origin rpy="1.5694791585075034 0.00015194814647356836 -0.0006505124711437826" xyz="0.04062006698890873 -3.726678941555769e-06 0.009339292204050375"/>
      <geometry>
        <mesh filename="package://orcahand_description/assets/urdf/right/visual/right_visual_tower_hull_mesh.stl"/>
      </geometry>
      <material name="white"/>
    </visual>
    <collision name="right_collision_tower_hull_mesh">
      <origin rpy="1.5691929949477865 -6.931644826568828e-05 -0.0012916867662787768" xyz="0.04061884697236149 7.083739226185091e-06 0.009306225228503611"/>
      <geometry>
        <mesh filename="package://orcahand_description/assets/urdf/right/collision/right_collision_tower_hull_mesh.stl"/>
      </geometry>
      <material name="white"/>
    </collision>
    <visual name="right_visual_tower_text_mesh">
      <origin rpy="8.992806499463768e-14 -1.570241143557443 1.5988186561911613" xyz="0.040617526582081696 4.362558106779257e-06 0.02737731026837054"/>
      <geometry>
        <mesh filename="package://orcahand_description/assets/urdf/right/visual/right_visual_tower_text_mesh.stl"/>
      </geometry>
      <material name="white"/>
    </visual>
    <collision name="right_collision_tower_text_mesh">
      <origin rpy="-2.239658800831686 -1.5545672668594075 -2.4480790171423275" xyz="0.04068345506360967 -0.0011250828560853416 0.027716099517902396"/>
      <geometry>
        <mesh filename="package://orcahand_description/assets/urdf/right/collision/right_collision_tower_text_mesh.stl"/>
      </geometry>
      <material name="white"/>
    </collision>
  </link>
  <link name="right_palm">
    <inertial>
      <origin rpy="1.67519 0.04750000000000032 1.55556" xyz="0.00193 -0.00052 -0.00664"/>
      <mass value="0.0257"/>
      <inertia ixx="1.612e-05" ixy="0" ixz="0" iyy="1.151e-05" iyz="0" izz="6.72e-06"/>
    </inertial>
    <visual name="right_visual_palm_mesh">
      <origin rpy="2.01172521777585 0.047179539585598285 1.531383022156099" xyz="0.0015568393804010381 0.00032366355975666324 -0.011896430343868667"/>
      <geometry>
        <mesh filename="package://orcahand_description/assets/urdf/right/visual/right_visual_palm_mesh.stl"/>
      </geometry>
      <material name="white"/>
    </visual>
    <collision name="right_collision_palm_mesh">
      <origin rpy="2.026338195778868 0.044917456181218895 1.531847751735018" xyz="0.0015796019462848588 0.0001376248446814945 -0.011923873250196919"/>
      <geometry>
        <mesh filename="package://orcahand_description/assets/urdf/right/collision/right_collision_palm_mesh.stl"/>
      </geometry>
      <material name="white"/>
    </collision>
    <visual name="right_visual_palm_skin_mesh">
      <origin rpy="1.7666058493725336 0.1563942094199331 1.6505205003593353" xyz="0.005673309514830851 -0.0012702684906836111 -0.001744430321194409"/>
      <geometry>
        <mesh filename="package://orcahand_description/assets/urdf/right/visual/right_visual_palm_skin_mesh.stl"/>
      </geometry>
      <material name="white"/>
    </visual>
    <collision name="right_collision_palm_skin_mesh">
      <origin rpy="1.8840619193629062 0.16785003095386486 1.6839920915628581" xyz="0.008013832397891144 -0.001293701510845759 -0.0015696747425978242"/>
      <geometry>
        <mesh filename="package://orcahand_description/assets/urdf/right/collision/right_collision_palm_skin_mesh.stl"/>
      </geometry>
      <material name="white"/>
    </collision>
  </link>
  <link name="right_wrist_jointbody">
    <inertial>
      <origin rpy="0.0 0.0 0.0" xyz="0.0 0.0 0.0"/>
      <mass value="0.001"/>
      <inertia ixx="1e-09" ixy="0" ixz="0" iyy="1e-09" iyz="0" izz="1e-09"/>
    </inertial>
  </link>
  <joint name="right_wrist" type="revolute">
    <parent link="right_tower"/>
    <child link="right_wrist_jointbody"/>
    <origin rpy="0.0 0.0 0.0" xyz="0.04063 0.0 0.10486999999999999"/>
    <axis xyz="1.0 0.0 0.0"/>
    <limit effort="100" lower="-0.6736" upper="0.8972" velocity="100"/>
  </joint>
  <joint name="right_wrist_offset" type="fixed">
    <parent link="right_wrist_jointbody"/>
    <child link="right_palm"/>
    <origin rpy="0.0 0.0 0.0" xyz="-0.002 0.00144 0.03872"/>
  </joint>
  <link name="right_thumb_mp">
    <inertial>
      <origin rpy="0.0 0.016249999999999876 0.0" xyz="0.00247 0.0 0.004"/>
      <mass value="0.00586"/>
      <inertia ixx="8.4e-07" ixy="0" ixz="0" iyy="6.6e-07" iyz="0" izz="2.7e-07"/>
    </inertial>
    <visual name="right_visual_thumb_mp_mesh">
      <origin rpy="-0.00450638440425983 -0.0029041941261005455 0.0" xyz="0.0026672782758389094 -3.6617030073895996e-06 0.0032021510136003503"/>
      <geometry>
        <mesh filename="package://orcahand_description/assets/urdf/right/visual/right_visual_thumb_mp_mesh.stl"/>
      </geometry>
      <material name="white"/>
    </visual>
    <collision name="right_collision_thumb_mp_mesh">
      <origin rpy="-0.004051421860145692 0.0 0.0" xyz="0.0025186274059406416 1.1817094343651893e-05 0.0033325772179257306"/>
      <geometry>
        <mesh filename="package://orcahand_description/assets/urdf/right/collision/right_collision_thumb_mp_mesh.stl"/>
      </geometry>
      <material name="white"/>
    </collision>
  </link>
  <link name="right_thumb_mcp_jointbody">
    <inertial>
      <origin rpy="0.0 0.0 0.0" xyz="0.0 0.0 0.0"/>
      <mass value="0.001"/>
      <inertia ixx="1e-09" ixy="0" ixz="0" iyy="1e-09" iyz="0" izz="1e-09"/>
    </inertial>
  </link>
  <joint name="right_thumb_mcp" type="revolute">
    <parent link="right_palm"/>
    <child link="right_thumb_mcp_jointbody"/>
    <origin rpy="0.5385700000000002 -0.05594999999999972 -1.27047" xyz="-0.02821 0.01777 -0.01321"/>
    <axis xyz="0.0 0.0 -1.0"/>
    <limit effort="100" lower="-0.87266" upper="0.87266" velocity="100"/>
  </joint>
  <joint name="right_thumb_mcp_offset" type="fixed">
    <parent link="right_thumb_mcp_jointbody"/>
    <child link="right_thumb_mp"/>
    <origin rpy="0.0 0.0 0.0" xyz="-0.0 -0.0 -0.0"/>
  </joint>
  <link name="right_thumb_pp">
    <inertial>
      <origin rpy="1.5708 0.7739199999999999 1.5708" xyz="0.01848 1e-05 2e-05"/>
      <mass value="0.00655"/>
      <inertia ixx="7.5e-07" ixy="0" ixz="0" iyy="7.1e-07" iyz="0" izz="3e-07"/>
    </inertial>
    <visual name="right_visual_thumb_pp_mesh">
      <origin rpy="-1.6017800681828298 -1.1287165327427504 -1.5432562301164818" xyz="0.01772057472979195 1.0070925191614284e-05 -0.00010493568910233946"/>
      <geometry>
        <mesh filename="package://orcahand_description/assets/urdf/right/visual/right_visual_thumb_pp_mesh.stl"/>
      </geometry>
      <material name="white"/>
    </visual>
    <collision name="right_collision_thumb_pp_mesh">
      <origin rpy="-1.588892025872152 -1.3512360913096229 -1.5473903377526785" xyz="0.01727473106987278 2.0812531064334476e-05 -0.00010892038972696916"/>
      <geometry>
        <mesh filename="package://orcahand_description/assets/urdf/right/collision/right_collision_thumb_pp_mesh.stl"/>
      </geometry>
      <material name="white"/>
    </collision>
  </link>
  <link name="right_thumb_abd_jointbody">
    <inertial>
      <origin rpy="0.0 0.0 0.0" xyz="0.0 0.0 0.0"/>
      <mass value="0.001"/>
      <inertia ixx="1e-09" ixy="0" ixz="0" iyy="1e-09" iyz="0" izz="1e-09"/>
    </inertial>
  </link>
  <joint name="right_thumb_abd" type="revolute">
    <parent link="right_thumb_mp"/>
    <child link="right_thumb_abd_jointbody"/>
    <origin rpy="-1.22173 0.0 0.0" xyz="6.938893903907228e-18 0.0 0.0"/>
    <axis xyz="0.0 0.34202085907197166 0.9396923602752502"/>
    <limit effort="100" lower="-1.08211" upper="0.0" velocity="100"/>
  </joint>
  <joint name="right_thumb_abd_offset" type="fixed">
    <parent link="right_thumb_abd_jointbody"/>
    <child link="right_thumb_pp"/>
    <origin rpy="0.0 0.0 0.0" xyz="-0.03 -0.0 -0.0"/>
  </joint>
  <link name="right_thumb_ip">
    <inertial>
      <origin rpy="0.0003700000000000001 0.03263000000000016 0.00034" xyz="0.00135 2e-05 0.01383"/>
      <mass value="0.01402"/>
      <inertia ixx="1.7e-06" ixy="0" ixz="0" iyy="1.64e-06" iyz="0" izz="5.9e-07"/>
    </inertial>
    <visual name="right_visual_thumb_ip_mesh">
      <origin rpy="0.0 0.04338716477372251 0.0" xyz="0.0012998948492342203 7.159773213648307e-06 0.013619877706625217"/>
      <geometry>
        <mesh filename="package://orcahand_description/assets/urdf/right/visual/right_visual_thumb_ip_mesh.stl"/>
      </geometry>
      <material name="white"/>
    </visual>
    <collision name="right_collision_thumb_ip_mesh">
      <origin rpy="0.00708255798627546 0.04763590113115046 0.0" xyz="0.0013560375396256981 0.00012710825491742077 0.013446327660739959"/>
      <geometry>
        <mesh filename="package://orcahand_description/assets/urdf/right/collision/right_collision_thumb_ip_mesh.stl"/>
      </geometry>
      <material name="white"/>
    </collision>
    <visual name="right_visual_thumb_ip_skin_mesh">
      <origin rpy="3.141592653589793 -1.2480960827956862 0.0" xyz="0.0015424443589898442 1.6522252825510055e-07 0.016259641785170875"/>
      <geometry>
        <mesh filename="package://orcahand_description/assets/urdf/right/visual/right_visual_thumb_ip_skin_mesh.stl"/>
      </geometry>
      <material name="white"/>
    </visual>
    <collision name="right_collision_thumb_ip_skin_mesh">
      <origin rpy="3.141592653589793 -1.243771833702049 0.0" xyz="0.0015528244655451595 6.48072440430664e-06 0.016246657621879965"/>
      <geometry>
        <mesh filename="package://orcahand_description/assets/urdf/right/collision/right_collision_thumb_ip_skin_mesh.stl"/>
      </geometry>
      <material name="white"/>
    </collision>
  </link>
  <link name="right_thumb_pip_jointbody">
    <inertial>
      <origin rpy="0.0 0.0 0.0" xyz="0.0 0.0 0.0"/>
      <mass value="0.001"/>
      <inertia ixx="1e-09" ixy="0" ixz="0" iyy="1e-09" iyz="0" izz="1e-09"/>
    </inertial>
  </link>
  <joint name="right_thumb_pip" type="revolute">
    <parent link="right_thumb_pp"/>
    <child link="right_thumb_pip_jointbody"/>
    <origin rpy="-2.6535897934554242e-06 1.5707926535897934 3.141592653589793" xyz="0.0 0.0 0.0"/>
    <axis xyz="0.0 -1.0 0.0"/>
    <limit effort="100" lower="-0.7944" upper="1.23" velocity="100"/>
  </joint>
  <joint name="right_thumb_pip_offset" type="fixed">
    <parent link="right_thumb_pip_jointbody"/>
    <child link="right_thumb_ip"/>
    <origin rpy="0.0 0.0 0.0" xyz="-0.0 -0.0 -0.0"/>
  </joint>
  <link name="right_thumb_dp">
    <inertial>
      <origin rpy="0.00075 0.08211000000000013 0.00013000000000000002" xyz="0.00233 1e-05 0.01133"/>
      <mass value="0.0132"/>
      <inertia ixx="1.4e-06" ixy="0" ixz="0" iyy="1.37e-06" iyz="0" izz="4.4e-07"/>
    </inertial>
    <visual name="right_visual_thumb_dp_mesh">
      <origin rpy="0.0 0.24698289481892632 0.0" xyz="0.001737692119750562 -5.352917438125722e-06 0.005127321105400321"/>
      <geometry>
        <mesh filename="package://orcahand_description/assets/urdf/right/visual/right_visual_thumb_dp_mesh.stl"/>
      </geometry>
      <material name="white"/>
    </visual>
    <collision name="right_collision_thumb_dp_mesh">
      <origin rpy="0.24272423187789072 -0.008190712846545711 1.5687682825082248" xyz="0.0020244971365026335 3.68319791392775e-05 0.005533677984084769"/>
      <geometry>
        <mesh filename="package://orcahand_description/assets/urdf/right/collision/right_collision_thumb_dp_mesh.stl"/>
      </geometry>
      <material name="white"/>
    </collision>
    <visual name="right_visual_thumb_dp_skin_mesh">
      <origin rpy="3.141592653589793 -0.40239793279263236 0.0" xyz="0.002793435568551968 -6.14386555467744e-07 0.016601042013200628"/>
      <geometry>
        <mesh filename="package://orcahand_description/assets/urdf/right/visual/right_visual_thumb_dp_skin_mesh.stl"/>
      </geometry>
      <material name="white"/>
    </visual>
    <collision name="right_collision_thumb_dp_skin_mesh">
      <origin rpy="3.141592653589793 -0.3963953079219906 0.0" xyz="0.002785448336058668 -6.944475247259374e-06 0.016557497442018437"/>
      <geometry>
        <mesh filename="package://orcahand_description/assets/urdf/right/collision/right_collision_thumb_dp_skin_mesh.stl"/>
      </geometry>
      <material name="white"/>
    </collision>
  </link>
  <link name="right_thumb_dip_jointbody">
    <inertial>
      <origin rpy="0.0 0.0 0.0" xyz="0.0 0.0 0.0"/>
      <mass value="0.001"/>
      <inertia ixx="1e-09" ixy="0" ixz="0" iyy="1e-09" iyz="0" izz="1e-09"/>
    </inertial>
  </link>
  <joint name="right_thumb_dip" type="revolute">
    <parent link="right_thumb_ip"/>
    <child link="right_thumb_dip_jointbody"/>
    <origin rpy="0.0 0.0 0.0" xyz="0.0005 0.0 0.033"/>
    <axis xyz="0.0 -1.0 0.0"/>
    <limit effort="100" lower="-0.85384" upper="1.45" velocity="100"/>
  </joint>
  <joint name="right_thumb_dip_offset" type="fixed">
    <parent link="right_thumb_dip_jointbody"/>
    <child link="right_thumb_dp"/>
    <origin rpy="0.0 0.0 0.0" xyz="-0.0 -0.0 -0.0"/>
  </joint>
  <link name="right_thumb_fingertip">
    <inertial>
      <origin rpy="0.0 0.0 0.0" xyz="-0.003 0.0 0.025"/>
      <mass value="0.0"/>
      <inertia ixx="0.0" ixy="0" ixz="0" iyy="0.0" iyz="0" izz="0.0"/>
    </inertial>
  </link>
  <joint name="thumb_dp2right_thumb_fingertip_fixed_offset" type="fixed">
    <parent link="right_thumb_dp"/>
    <child link="right_thumb_fingertip"/>
    <origin rpy="0.0 0.0 0.0" xyz="-0.003 0.0 0.025"/>
  </joint>
  <link name="right_index_mp">
    <inertial>
      <origin rpy="-2.6535897932333796e-06 -1.5707926535897931 3.141592653589793" xyz="0.01155 0.0 -4e-05"/>
      <mass value="0.00498"/>
      <inertia ixx="3.4e-07" ixy="0" ixz="0" iyy="3.1e-07" iyz="0" izz="2e-07"/>
    </inertial>
    <visual name="right_visual_index_mp_mesh">
      <origin rpy="3.1297715721932393 -1.5066740246432395 2.4424906541753444e-15" xyz="0.010698479000335614 -1.389065483476104e-05 -0.00027878809319396305"/>
      <geometry>
        <mesh filename="package://orcahand_description/assets/urdf/right/visual/right_visual_index_mp_mesh.stl"/>
      </geometry>
      <material name="white"/>
    </visual>
    <collision name="right_collision_index_mp_mesh">
      <origin rpy="0.928212641576985 -1.5147947849129795 2.212627507721145" xyz="0.01047824184159959 -4.456734197189478e-05 -0.00016480462181888062"/>
      <geometry>
        <mesh filename="package://orcahand_description/assets/urdf/right/collision/right_collision_index_mp_mesh.stl"/>
      </geometry>
      <material name="white"/>
    </collision>
  </link>
  <link name="right_index_abd_jointbody">
    <inertial>
      <origin rpy="0.0 0.0 0.0" xyz="0.0 0.0 0.0"/>
      <mass value="0.001"/>
      <inertia ixx="1e-09" ixy="0" ixz="0" iyy="1e-09" iyz="0" izz="1e-09"/>
    </inertial>
  </link>
  <joint name="right_index_abd" type="revolute">
    <parent link="right_palm"/>
    <child link="right_index_abd_jointbody"/>
    <origin rpy="1.6066999999999996 1.13552 -0.05339000000000049" xyz="-0.024088797002689358 0.0018999642829399502 0.025164928786148736"/>
    <axis xyz="0.0 0.0 -1.0"/>
    <limit effort="100" lower="-1.04577" upper="0.24577" velocity="100"/>
  </joint>
  <joint name="right_index_abd_offset" type="fixed">
    <parent link="right_index_abd_jointbody"/>
    <child link="right_index_mp"/>
    <origin rpy="0.0 0.0 0.0" xyz="-0.02 -0.0 -0.0"/>
  </joint>
  <link name="right_index_pp">
    <inertial>
      <origin rpy="0.00034 0.020550000000000068 0.00038" xyz="0.00135 2e-05 0.01637"/>
      <mass value="0.0165"/>
      <inertia ixx="2.39e-06" ixy="0" ixz="0" iyy="2.31e-06" iyz="0" izz="7.1e-07"/>
    </inertial>
    <visual name="right_visual_index_pp_mesh">
      <origin rpy="0.005516325755706635 0.035101984887858206 0.03910570256058449" xyz="0.0012791981098529209 4.322204569499314e-05 0.016098661080179"/>
      <geometry>
        <mesh filename="package://orcahand_description/assets/urdf/right/visual/right_visual_index_pp_mesh.stl"/>
      </geometry>
      <material name="white"/>
    </visual>
    <collision name="right_collision_index_pp_mesh">
      <origin rpy="0.0 0.042883356216690816 0.0" xyz="0.0013516740131344841 1.1247422892215125e-05 0.015681803525061735"/>
      <geometry>
        <mesh filename="package://orcahand_description/assets/urdf/right/collision/right_collision_index_pp_mesh.stl"/>
      </geometry>
      <material name="white"/>
    </collision>
    <visual name="right_visual_index_pp_skin_mesh">
      <origin rpy="3.141592653589793 -0.8345404465359767 0.0" xyz="0.0016617007377281573 7.13567847691717e-08 0.018763861638214734"/>
      <geometry>
        <mesh filename="package://orcahand_description/assets/urdf/right/visual/right_visual_index_pp_skin_mesh.stl"/>
      </geometry>
      <material name="white"/>
    </visual>
    <collision name="right_collision_index_pp_skin_mesh">
      <origin rpy="3.141592653589793 -0.8259683678608123 0.0" xyz="0.0016773866527582534 -5.5310131701629075e-06 0.018740870134460883"/>
      <geometry>
        <mesh filename="package://orcahand_description/assets/urdf/right/collision/right_collision_index_pp_skin_mesh.stl"/>
      </geometry>
      <material name="white"/>
    </collision>
  </link>
  <link name="right_index_mcp_jointbody">
    <inertial>
      <origin rpy="0.0 0.0 0.0" xyz="0.0 0.0 0.0"/>
      <mass value="0.001"/>
      <inertia ixx="1e-09" ixy="0" ixz="0" iyy="1e-09" iyz="0" izz="1e-09"/>
    </inertial>
  </link>
  <joint name="right_index_mcp" type="revolute">
    <parent link="right_index_mp"/>
    <child link="right_index_mcp_jointbody"/>
    <origin rpy="3.141592653589793 -1.5707926535897931 3.141592653589793" xyz="0.0 0.0 0.0"/>
    <axis xyz="0.0 -1.0 0.0"/>
    <limit effort="100" lower="-0.34907" upper="1.65806" velocity="100"/>
  </joint>
  <joint name="right_index_mcp_offset" type="fixed">
    <parent link="right_index_mcp_jointbody"/>
    <child link="right_index_pp"/>
    <origin rpy="0.0 0.0 0.0" xyz="-0.0 -0.0 -0.0"/>
  </joint>
  <link name="right_index_ip">
    <inertial>
      <origin rpy="-0.00042000000000000023 -0.18548999999999993 0.004400000000000001" xyz="0.00071 1e-05 0.01929"/>
      <mass value="0.01521"/>
      <inertia ixx="2.08e-06" ixy="0" ixz="0" iyy="2.06e-06" iyz="0" izz="5.4e-07"/>
    </inertial>
    <visual name="right_visual_index_ip_mesh">
      <origin rpy="-0.03448776902850714 -0.0034390239986910043 1.5709149778710771" xyz="0.0010416798025929732 7.836534536637715e-05 0.011793743862640304"/>
      <geometry>
        <mesh filename="package://orcahand_description/assets/urdf/right/visual/right_visual_index_ip_mesh.stl"/>
      </geometry>
      <material name="white"/>
    </visual>
    <collision name="right_collision_index_ip_mesh">
      <origin rpy="0.0018005943049513862 0.0 1.5707963267948966" xyz="0.001264526142413497 -1.637119615337525e-05 0.01147202326458154"/>
      <geometry>
        <mesh filename="package://orcahand_description/assets/urdf/right/collision/right_collision_index_ip_mesh.stl"/>
      </geometry>
      <material name="white"/>
    </collision>
    <visual name="right_visual_index_ip_skin_mesh">
      <origin rpy="0.0 -0.4563594541722644 0.0" xyz="0.0006177579160319044 -2.8394632435300543e-07 0.02298191534250252"/>
      <geometry>
        <mesh filename="package://orcahand_description/assets/urdf/right/visual/right_visual_index_ip_skin_mesh.stl"/>
      </geometry>
      <material name="white"/>
    </visual>
    <collision name="right_collision_index_ip_skin_mesh">
      <origin rpy="0.0 -0.4457042297154219 0.0" xyz="0.0006216739383467692 2.432607491983251e-06 0.02302104994067657"/>
      <geometry>
        <mesh filename="package://orcahand_description/assets/urdf/right/collision/right_collision_index_ip_skin_mesh.stl"/>
      </geometry>
      <material name="white"/>
    </collision>
  </link>
  <link name="right_index_pip_jointbody">
    <inertial>
      <origin rpy="0.0 0.0 0.0" xyz="0.0 0.0 0.0"/>
      <mass value="0.001"/>
      <inertia ixx="1e-09" ixy="0" ixz="0" iyy="1e-09" iyz="0" izz="1e-09"/>
    </inertial>
  </link>
  <joint name="right_index_pip" type="revolute">
    <parent link="right_index_pp"/>
    <child link="right_index_pip_jointbody"/>
    <origin rpy="0.0 0.0 0.0" xyz="0.0005 0.0 0.038"/>
    <axis xyz="0.0 -1.0 0.0"/>
    <limit effort="100" lower="-0.34907" upper="1.88496" velocity="100"/>
  </joint>
  <joint name="right_index_pip_offset" type="fixed">
    <parent link="right_index_pip_jointbody"/>
    <child link="right_index_ip"/>
    <origin rpy="0.0 0.0 0.0" xyz="-0.0 -0.0 -0.0"/>
  </joint>
  <link name="right_index_fingertip">
    <inertial>
      <origin rpy="0.0 0.0 0.0" xyz="-0.009 0.0 0.035"/>
      <mass value="0.0"/>
      <inertia ixx="0.0" ixy="0" ixz="0" iyy="0.0" iyz="0" izz="0.0"/>
    </inertial>
  </link>
  <joint name="right_index_ip2right_index_fingertip_fixed_offset" type="fixed">
    <parent link="right_index_ip"/>
    <child link="right_index_fingertip"/>
    <origin rpy="0.0 0.0 0.0" xyz="-0.009 0.0 0.035"/>
  </joint>
  <link name="right_middle_mp">
    <inertial>
      <origin rpy="-2.6535897932333796e-06 -1.5707926535897931 3.141592653589793" xyz="0.01155 0.0 -4e-05"/>
      <mass value="0.00498"/>
      <inertia ixx="3.4e-07" ixy="0" ixz="0" iyy="3.1e-07" iyz="0" izz="2e-07"/>
    </inertial>
    <visual name="right_visual_middle_mp_mesh">
      <origin rpy="3.1297715721932393 -1.5066740246432395 2.4424906541753444e-15" xyz="0.010698479000335614 -1.389065483476104e-05 -0.00027878809319396305"/>
      <geometry>
        <mesh filename="package://orcahand_description/assets/urdf/right/visual/right_visual_middle_mp_mesh.stl"/>
      </geometry>
      <material name="white"/>
    </visual>
    <collision name="right_collision_middle_mp_mesh">
      <origin rpy="0.928212641576985 -1.5147947849129795 2.212627507721145" xyz="0.01047824184159959 -4.456734197189478e-05 -0.00016480462181888062"/>
      <geometry>
        <mesh filename="package://orcahand_description/assets/urdf/right/collision/right_collision_middle_mp_mesh.stl"/>
      </geometry>
      <material name="white"/>
    </collision>
  </link>
  <link name="right_middle_abd_jointbody">
    <inertial>
      <origin rpy="0.0 0.0 0.0" xyz="0.0 0.0 0.0"/>
      <mass value="0.001"/>
      <inertia ixx="1e-09" ixy="0" ixz="0" iyy="1e-09" iyz="0" izz="1e-09"/>
    </inertial>
  </link>
  <joint name="right_middle_abd" type="revolute">
    <parent link="right_palm"/>
    <child link="right_middle_abd_jointbody"/>
    <origin rpy="-1.5707926536208807 1.5707926535897934 3.141592653558706" xyz="-7.346410206776621e-08 0.0 0.030000000000134926"/>
    <axis xyz="0.0 0.0 -1.0"/>
    <limit effort="100" lower="-0.64577" upper="0.64577" velocity="100"/>
  </joint>
  <joint name="right_middle_abd_offset" type="fixed">
    <parent link="right_middle_abd_jointbody"/>
    <child link="right_middle_mp"/>
    <origin rpy="0.0 0.0 0.0" xyz="-0.02 -0.0 -0.0"/>
  </joint>
  <link name="right_middle_pp">
    <inertial>
      <origin rpy="-2.9999999999999916e-05 0.013859999999999983 0.0005999999999999998" xyz="0.00144 2e-05 0.02021"/>
      <mass value="0.02006"/>
      <inertia ixx="3.78e-06" ixy="0" ixz="0" iyy="3.69e-06" iyz="0" izz="8.9e-07"/>
    </inertial>
    <visual name="right_visual_middle_pp_mesh">
      <origin rpy="0.004564296284170381 0.027656376334468602 0.037580505677349094" xyz="0.001283421930192045 3.6963342684240676e-05 0.02022720775953102"/>
      <geometry>
        <mesh filename="package://orcahand_description/assets/urdf/right/visual/right_visual_middle_pp_mesh.stl"/>
      </geometry>
      <material name="white"/>
    </visual>
    <collision name="right_collision_middle_pp_mesh">
      <origin rpy="-0.0006410664486678006 0.029880005436222712 -5.421010862427522e-20" xyz="0.001339380770656077 -6.845101857801683e-06 0.02011933923689832"/>
      <geometry>
        <mesh filename="package://orcahand_description/assets/urdf/right/collision/right_collision_middle_pp_mesh.stl"/>
      </geometry>
      <material name="white"/>
    </collision>
    <visual name="right_visual_middle_pp_skin_mesh">
      <origin rpy="0.0 -0.22312530126972074 0.0" xyz="0.001729699116189442 2.0144468929163878e-08 0.022938288977938984"/>
      <geometry>
        <mesh filename="package://orcahand_description/assets/urdf/right/visual/right_visual_middle_pp_skin_mesh.stl"/>
      </geometry>
      <material name="white"/>
    </visual>
    <collision name="right_collision_middle_pp_skin_mesh">
      <origin rpy="0.0 -0.22006061767397878 0.0" xyz="0.0017525848624676125 2.7252940732883304e-06 0.022885135333659"/>
      <geometry>
        <mesh filename="package://orcahand_description/assets/urdf/right/collision/right_collision_middle_pp_skin_mesh.stl"/>
      </geometry>
      <material name="white"/>
    </collision>
  </link>
  <link name="right_middle_mcp_jointbody">
    <inertial>
      <origin rpy="0.0 0.0 0.0" xyz="0.0 0.0 0.0"/>
      <mass value="0.001"/>
      <inertia ixx="1e-09" ixy="0" ixz="0" iyy="1e-09" iyz="0" izz="1e-09"/>
    </inertial>
  </link>
  <joint name="right_middle_mcp" type="revolute">
    <parent link="right_middle_mp"/>
    <child link="right_middle_mcp_jointbody"/>
    <origin rpy="3.141592653589793 -1.5707926535897931 3.141592653589793" xyz="0.0 0.0 0.0"/>
    <axis xyz="0.0 -1.0 0.0"/>
    <limit effort="100" lower="-0.34907" upper="1.58825" velocity="100"/>
  </joint>
  <joint name="right_middle_mcp_offset" type="fixed">
    <parent link="right_middle_mcp_jointbody"/>
    <child link="right_middle_pp"/>
    <origin rpy="0.0 0.0 0.0" xyz="-0.0 -0.0 -0.0"/>
  </joint>
  <link name="right_middle_ip">
    <inertial>
      <origin rpy="-0.00042000000000000023 -0.18548999999999993 0.004400000000000001" xyz="0.00071 1e-05 0.01929"/>
      <mass value="0.01521"/>
      <inertia ixx="2.08e-06" ixy="0" ixz="0" iyy="2.06e-06" iyz="0" izz="5.4e-07"/>
    </inertial>
    <visual name="right_visual_middle_ip_mesh">
      <origin rpy="-0.03448776902850714 -0.0034390239986910043 1.5709149778710771" xyz="0.0010416798025929732 7.836534536637715e-05 0.011793743862640304"/>
      <geometry>
        <mesh filename="package://orcahand_description/assets/urdf/right/visual/right_visual_middle_ip_mesh.stl"/>
      </geometry>
      <material name="white"/>
    </visual>
    <collision name="right_collision_middle_ip_mesh">
      <origin rpy="0.0018005943049513862 0.0 1.5707963267948966" xyz="0.001264526142413497 -1.637119615337525e-05 0.01147202326458154"/>
      <geometry>
        <mesh filename="package://orcahand_description/assets/urdf/right/collision/right_collision_middle_ip_mesh.stl"/>
      </geometry>
      <material name="white"/>
    </collision>
    <visual name="right_visual_middle_ip_skin_mesh">
      <origin rpy="0.0 -0.4563594541722644 0.0" xyz="0.0006177579160319044 -2.8394632435300543e-07 0.02298191534250252"/>
      <geometry>
        <mesh filename="package://orcahand_description/assets/urdf/right/visual/right_visual_middle_ip_skin_mesh.stl"/>
      </geometry>
      <material name="white"/>
    </visual>
    <collision name="right_collision_middle_ip_skin_mesh">
      <origin rpy="0.0 -0.4457042297154219 0.0" xyz="0.0006216739383467692 2.432607491983251e-06 0.02302104994067657"/>
      <geometry>
        <mesh filename="package://orcahand_description/assets/urdf/right/collision/right_collision_middle_ip_skin_mesh.stl"/>
      </geometry>
      <material name="white"/>
    </collision>
  </link>
  <link name="right_middle_pip_jointbody">
    <inertial>
      <origin rpy="0.0 0.0 0.0" xyz="0.0 0.0 0.0"/>
      <mass value="0.001"/>
      <inertia ixx="1e-09" ixy="0" ixz="0" iyy="1e-09" iyz="0" izz="1e-09"/>
    </inertial>
  </link>
  <joint name="right_middle_pip" type="revolute">
    <parent link="right_middle_pp"/>
    <child link="right_middle_pip_jointbody"/>
    <origin rpy="0.0 0.0 0.0" xyz="0.0005 0.0 0.046"/>
    <axis xyz="0.0 -1.0 0.0"/>
    <limit effort="100" lower="-0.34907" upper="1.8675" velocity="100"/>
  </joint>
  <joint name="right_middle_pip_offset" type="fixed">
    <parent link="right_middle_pip_jointbody"/>
    <child link="right_middle_ip"/>
    <origin rpy="0.0 0.0 0.0" xyz="-0.0 -0.0 -0.0"/>
  </joint>
  <link name="right_middle_fingertip">
    <inertial>
      <origin rpy="0.0 0.0 0.0" xyz="-0.009 0.0 0.035"/>
      <mass value="0.0"/>
      <inertia ixx="0.0" ixy="0" ixz="0" iyy="0.0" iyz="0" izz="0.0"/>
    </inertial>
  </link>
  <joint name="right_middle_ip2right_index_fingertip_fixed_offset" type="fixed">
    <parent link="right_middle_ip"/>
    <child link="right_middle_fingertip"/>
    <origin rpy="0.0 0.0 0.0" xyz="-0.009 0.0 0.035"/>
  </joint>
  <link name="right_ring_mp">
    <inertial>
      <origin rpy="-2.6535897932333796e-06 -1.5707926535897931 3.141592653589793" xyz="0.01155 0.0 -4e-05"/>
      <mass value="0.00498"/>
      <inertia ixx="3.4e-07" ixy="0" ixz="0" iyy="3.1e-07" iyz="0" izz="2e-07"/>
    </inertial>
    <visual name="right_visual_ring_mp_mesh">
      <origin rpy="3.1297715721932393 -1.5066740246432395 2.4424906541753444e-15" xyz="0.010698479000335614 -1.389065483476104e-05 -0.00027878809319396305"/>
      <geometry>
        <mesh filename="package://orcahand_description/assets/urdf/right/visual/right_visual_ring_mp_mesh.stl"/>
      </geometry>
      <material name="white"/>
    </visual>
    <collision name="right_collision_ring_mp_mesh">
      <origin rpy="0.928212641576985 -1.5147947849129795 2.212627507721145" xyz="0.01047824184159959 -4.456734197189478e-05 -0.00016480462181888062"/>
      <geometry>
        <mesh filename="package://orcahand_description/assets/urdf/right/collision/right_collision_ring_mp_mesh.stl"/>
      </geometry>
      <material name="white"/>
    </collision>
  </link>
  <link name="right_ring_abd_jointbody">
    <inertial>
      <origin rpy="0.0 0.0 0.0" xyz="0.0 0.0 0.0"/>
      <mass value="0.001"/>
      <inertia ixx="1e-09" ixy="0" ixz="0" iyy="1e-09" iyz="0" izz="1e-09"/>
    </inertial>
  </link>
  <joint name="right_ring_abd" type="revolute">
    <parent link="right_palm"/>
    <child link="right_ring_abd_jointbody"/>
    <origin rpy="-1.5359699999999998 1.30836 -3.05441" xyz="0.021521022061295733 0.0015382095479525787 0.020824784431525818"/>
    <axis xyz="0.0 0.0 -1.0"/>
    <limit effort="100" lower="-0.47577" upper="0.80577" velocity="100"/>
  </joint>
  <joint name="right_ring_abd_offset" type="fixed">
    <parent link="right_ring_abd_jointbody"/>
    <child link="right_ring_mp"/>
    <origin rpy="0.0 0.0 0.0" xyz="-0.02 -0.0 -0.0"/>
  </joint>
  <link name="right_ring_pp">
    <inertial>
      <origin rpy="-2.9999999999999916e-05 0.013859999999999983 0.0005999999999999998" xyz="0.00144 2e-05 0.02021"/>
      <mass value="0.02006"/>
      <inertia ixx="3.78e-06" ixy="0" ixz="0" iyy="3.69e-06" iyz="0" izz="8.9e-07"/>
    </inertial>
    <visual name="right_visual_ring_pp_mesh">
      <origin rpy="0.004564296284170381 0.027656376334468602 0.037580505677349094" xyz="0.001283421930192045 3.6963342684240676e-05 0.02022720775953102"/>
      <geometry>
        <mesh filename="package://orcahand_description/assets/urdf/right/visual/right_visual_ring_pp_mesh.stl"/>
      </geometry>
      <material name="white"/>
    </visual>
    <collision name="right_collision_ring_pp_mesh">
      <origin rpy="-0.0006410664486678006 0.029880005436222712 -5.421010862427522e-20" xyz="0.001339380770656077 -6.845101857801683e-06 0.02011933923689832"/>
      <geometry>
        <mesh filename="package://orcahand_description/assets/urdf/right/collision/right_collision_ring_pp_mesh.stl"/>
      </geometry>
      <material name="white"/>
    </collision>
    <visual name="right_visual_ring_pp_skin_mesh">
      <origin rpy="0.0 -0.22312530126972074 0.0" xyz="0.001729699116189442 2.0144468929163878e-08 0.022938288977938984"/>
      <geometry>
        <mesh filename="package://orcahand_description/assets/urdf/right/visual/right_visual_ring_pp_skin_mesh.stl"/>
      </geometry>
      <material name="white"/>
    </visual>
    <collision name="right_collision_ring_pp_skin_mesh">
      <origin rpy="0.0 -0.22006061767397878 0.0" xyz="0.0017525848624676125 2.7252940732883304e-06 0.022885135333659"/>
      <geometry>
        <mesh filename="package://orcahand_description/assets/urdf/right/collision/right_collision_ring_pp_skin_mesh.stl"/>
      </geometry>
      <material name="white"/>
    </collision>
  </link>
  <link name="right_ring_mcp_jointbody">
    <inertial>
      <origin rpy="0.0 0.0 0.0" xyz="0.0 0.0 0.0"/>
      <mass value="0.001"/>
      <inertia ixx="1e-09" ixy="0" ixz="0" iyy="1e-09" iyz="0" izz="1e-09"/>
    </inertial>
  </link>
  <joint name="right_ring_mcp" type="revolute">
    <parent link="right_ring_mp"/>
    <child link="right_ring_mcp_jointbody"/>
    <origin rpy="3.141592653589793 -1.5707926535897931 3.141592653589793" xyz="0.0 0.0 0.0"/>
    <axis xyz="0.0 -1.0 0.0"/>
    <limit effort="100" lower="-0.34907" upper="1.58825" velocity="100"/>
  </joint>
  <joint name="right_ring_mcp_offset" type="fixed">
    <parent link="right_ring_mcp_jointbody"/>
    <child link="right_ring_pp"/>
    <origin rpy="0.0 0.0 0.0" xyz="-0.0 -0.0 -0.0"/>
  </joint>
  <link name="right_ring_ip">
    <inertial>
      <origin rpy="-0.00042000000000000023 -0.18548999999999993 0.004400000000000001" xyz="0.00071 1e-05 0.01929"/>
      <mass value="0.01521"/>
      <inertia ixx="2.08e-06" ixy="0" ixz="0" iyy="2.06e-06" iyz="0" izz="5.4e-07"/>
    </inertial>
    <visual name="right_visual_ring_ip_mesh">
      <origin rpy="-0.03448776902850714 -0.0034390239986910043 1.5709149778710771" xyz="0.0010416798025929732 7.836534536637715e-05 0.011793743862640304"/>
      <geometry>
        <mesh filename="package://orcahand_description/assets/urdf/right/visual/right_visual_ring_ip_mesh.stl"/>
      </geometry>
      <material name="white"/>
    </visual>
    <collision name="right_collision_ring_ip_mesh">
      <origin rpy="0.0018005943049513862 0.0 1.5707963267948966" xyz="0.001264526142413497 -1.637119615337525e-05 0.01147202326458154"/>
      <geometry>
        <mesh filename="package://orcahand_description/assets/urdf/right/collision/right_collision_ring_ip_mesh.stl"/>
      </geometry>
      <material name="white"/>
    </collision>
    <visual name="right_visual_ring_ip_skin_mesh">
      <origin rpy="0.0 -0.4563594541722644 0.0" xyz="0.0006177579160319044 -2.8394632435300543e-07 0.02298191534250252"/>
      <geometry>
        <mesh filename="package://orcahand_description/assets/urdf/right/visual/right_visual_ring_ip_skin_mesh.stl"/>
      </geometry>
      <material name="white"/>
    </visual>
    <collision name="right_collision_ring_ip_skin_mesh">
      <origin rpy="0.0 -0.4457042297154219 0.0" xyz="0.0006216739383467692 2.432607491983251e-06 0.02302104994067657"/>
      <geometry>
        <mesh filename="package://orcahand_description/assets/urdf/right/collision/right_collision_ring_ip_skin_mesh.stl"/>
      </geometry>
      <material name="white"/>
    </collision>
  </link>
  <link name="right_ring_pip_jointbody">
    <inertial>
      <origin rpy="0.0 0.0 0.0" xyz="0.0 0.0 0.0"/>
      <mass value="0.001"/>
      <inertia ixx="1e-09" ixy="0" ixz="0" iyy="1e-09" iyz="0" izz="1e-09"/>
    </inertial>
  </link>
  <joint name="right_ring_pip" type="revolute">
    <parent link="right_ring_pp"/>
    <child link="right_ring_pip_jointbody"/>
    <origin rpy="0.0 0.0 0.0" xyz="0.0005 0.0 0.046"/>
    <axis xyz="0.0 -1.0 0.0"/>
    <limit effort="100" lower="-0.34907" upper="1.8675" velocity="100"/>
  </joint>
  <joint name="right_ring_pip_offset" type="fixed">
    <parent link="right_ring_pip_jointbody"/>
    <child link="right_ring_ip"/>
    <origin rpy="0.0 0.0 0.0" xyz="-0.0 -0.0 -0.0"/>
  </joint>
  <link name="right_ring_fingertip">
    <inertial>
      <origin rpy="0.0 0.0 0.0" xyz="-0.009 0.0 0.035"/>
      <mass value="0.0"/>
      <inertia ixx="0.0" ixy="0" ixz="0" iyy="0.0" iyz="0" izz="0.0"/>
    </inertial>
  </link>
  <joint name="right_ring_ip2right_index_fingertip_fixed_offset" type="fixed">
    <parent link="right_ring_ip"/>
    <child link="right_ring_fingertip"/>
    <origin rpy="0.0 0.0 0.0" xyz="-0.009 0.0 0.035"/>
  </joint>
  <link name="right_pinky_mp">
    <inertial>
      <origin rpy="-2.6535897932333796e-06 -1.5707926535897931 3.141592653589793" xyz="0.01155 0.0 -4e-05"/>
      <mass value="0.00498"/>
      <inertia ixx="3.4e-07" ixy="0" ixz="0" iyy="3.1e-07" iyz="0" izz="2e-07"/>
    </inertial>
    <visual name="right_visual_pinky_mp_mesh">
      <origin rpy="3.1297715721932393 -1.5066740246432395 2.4424906541753444e-15" xyz="0.010698479000335614 -1.389065483476104e-05 -0.00027878809319396305"/>
      <geometry>
        <mesh filename="package://orcahand_description/assets/urdf/right/visual/right_visual_pinky_mp_mesh.stl"/>
      </geometry>
      <material name="white"/>
    </visual>
    <collision name="right_collision_pinky_mp_mesh">
      <origin rpy="0.928212641576985 -1.5147947849129795 2.212627507721145" xyz="0.01047824184159959 -4.456734197189478e-05 -0.00016480462181888062"/>
      <geometry>
        <mesh filename="package://orcahand_description/assets/urdf/right/collision/right_collision_pinky_mp_mesh.stl"/>
      </geometry>
      <material name="white"/>
    </collision>
  </link>
  <link name="right_pinky_abd_jointbody">
    <inertial>
      <origin rpy="0.0 0.0 0.0" xyz="0.0 0.0 0.0"/>
      <mass value="0.001"/>
      <inertia ixx="1e-09" ixy="0" ixz="0" iyy="1e-09" iyz="0" izz="1e-09"/>
    </inertial>
  </link>
  <joint name="right_pinky_abd" type="revolute">
    <parent link="right_palm"/>
    <child link="right_pinky_abd_jointbody"/>
    <origin rpy="-1.49694 0.8614899999999999 -2.8837299999999995" xyz="0.04258452932438962 0.004988143142003794 0.007243722937596895"/>
    <axis xyz="0.0 0.0 -1.0"/>
    <limit effort="100" lower="-0.12244" upper="1.1691" velocity="100"/>
  </joint>
  <joint name="right_pinky_abd_offset" type="fixed">
    <parent link="right_pinky_abd_jointbody"/>
    <child link="right_pinky_mp"/>
    <origin rpy="0.0 0.0 0.0" xyz="-0.02 -0.0 -0.0"/>
  </joint>
  <link name="right_pinky_pp">
    <inertial>
      <origin rpy="0.0003700000000000001 0.03263000000000016 0.00034" xyz="0.00135 2e-05 0.01383"/>
      <mass value="0.01402"/>
      <inertia ixx="1.7e-06" ixy="0" ixz="0" iyy="1.64e-06" iyz="0" izz="5.9e-07"/>
    </inertial>
    <visual name="right_visual_pinky_pp_mesh">
      <origin rpy="0.0 0.04338716477372251 0.0" xyz="0.0012998948492342203 7.159773213648307e-06 0.013619877706625217"/>
      <geometry>
        <mesh filename="package://orcahand_description/assets/urdf/right/visual/right_visual_pinky_pp_mesh.stl"/>
      </geometry>
      <material name="white"/>
    </visual>
    <collision name="right_collision_pinky_pp_mesh">
      <origin rpy="0.00708255798627546 0.04763590113115046 0.0" xyz="0.0013560375396256981 0.00012710825491742077 0.013446327660739959"/>
      <geometry>
        <mesh filename="package://orcahand_description/assets/urdf/right/collision/right_collision_pinky_pp_mesh.stl"/>
      </geometry>
      <material name="white"/>
    </collision>
    <visual name="right_visual_pinky_pp_skin_mesh">
      <origin rpy="3.141592653589793 -1.2480960827956862 0.0" xyz="0.0015424443589898442 1.6522252825510055e-07 0.016259641785170875"/>
      <geometry>
        <mesh filename="package://orcahand_description/assets/urdf/right/visual/right_visual_pinky_pp_skin_mesh.stl"/>
      </geometry>
      <material name="white"/>
    </visual>
    <collision name="right_collision_pinky_pp_skin_mesh">
      <origin rpy="3.141592653589793 -1.243771833702049 0.0" xyz="0.0015528244655451595 6.48072440430664e-06 0.016246657621879965"/>
      <geometry>
        <mesh filename="package://orcahand_description/assets/urdf/right/collision/right_collision_pinky_pp_skin_mesh.stl"/>
      </geometry>
      <material name="white"/>
    </collision>
  </link>
  <link name="right_pinky_mcp_jointbody">
    <inertial>
      <origin rpy="0.0 0.0 0.0" xyz="0.0 0.0 0.0"/>
      <mass value="0.001"/>
      <inertia ixx="1e-09" ixy="0" ixz="0" iyy="1e-09" iyz="0" izz="1e-09"/>
    </inertial>
  </link>
  <joint name="right_pinky_mcp" type="revolute">
    <parent link="right_pinky_mp"/>
    <child link="right_pinky_mcp_jointbody"/>
    <origin rpy="3.141592653589793 -1.5707926535897931 3.141592653589793" xyz="0.0 0.0 0.0"/>
    <axis xyz="0.0 -1.0 0.0"/>
    <limit effort="100" lower="-0.34907" upper="1.71042" velocity="100"/>
  </joint>
  <joint name="right_pinky_mcp_offset" type="fixed">
    <parent link="right_pinky_mcp_jointbody"/>
    <child link="right_pinky_pp"/>
    <origin rpy="0.0 0.0 0.0" xyz="-0.0 -0.0 -0.0"/>
  </joint>
  <link name="right_pinky_ip">
    <inertial>
      <origin rpy="-0.00042000000000000023 -0.18548999999999993 0.004400000000000001" xyz="0.00071 1e-05 0.01929"/>
      <mass value="0.01521"/>
      <inertia ixx="2.08e-06" ixy="0" ixz="0" iyy="2.06e-06" iyz="0" izz="5.4e-07"/>
    </inertial>
    <visual name="right_visual_pinky_ip_mesh">
      <origin rpy="-0.03448776902850714 -0.0034390239986910043 1.5709149778710771" xyz="0.0010416798025929732 7.836534536637715e-05 0.011793743862640304"/>
      <geometry>
        <mesh filename="package://orcahand_description/assets/urdf/right/visual/right_visual_pinky_ip_mesh.stl"/>
      </geometry>
      <material name="white"/>
    </visual>
    <collision name="right_collision_pinky_ip_mesh">
      <origin rpy="0.0018005943049513862 0.0 1.5707963267948966" xyz="0.001264526142413497 -1.637119615337525e-05 0.01147202326458154"/>
      <geometry>
        <mesh filename="package://orcahand_description/assets/urdf/right/collision/right_collision_pinky_ip_mesh.stl"/>
      </geometry>
      <material name="white"/>
    </collision>
    <visual name="right_visual_pinky_ip_skin_mesh">
      <origin rpy="0.0 -0.4563594541722644 0.0" xyz="0.0006177579160319044 -2.8394632435300543e-07 0.02298191534250252"/>
      <geometry>
        <mesh filename="package://orcahand_description/assets/urdf/right/visual/right_visual_pinky_ip_skin_mesh.stl"/>
      </geometry>
      <material name="white"/>
    </visual>
    <collision name="right_collision_pinky_ip_skin_mesh">
      <origin rpy="0.0 -0.4457042297154219 0.0" xyz="0.0006216739383467692 2.432607491983251e-06 0.02302104994067657"/>
      <geometry>
        <mesh filename="package://orcahand_description/assets/urdf/right/collision/right_collision_pinky_ip_skin_mesh.stl"/>
      </geometry>
      <material name="white"/>
    </collision>
  </link>
  <link name="right_pinky_pip_jointbody">
    <inertial>
      <origin rpy="0.0 0.0 0.0" xyz="0.0 0.0 0.0"/>
      <mass value="0.001"/>
      <inertia ixx="1e-09" ixy="0" ixz="0" iyy="1e-09" iyz="0" izz="1e-09"/>
    </inertial>
  </link>
  <joint name="right_pinky_pip" type="revolute">
    <parent link="right_pinky_pp"/>
    <child link="right_pinky_pip_jointbody"/>
    <origin rpy="0.0 0.0 0.0" xyz="0.0005 0.0 0.033"/>
    <axis xyz="0.0 -1.0 0.0"/>
    <limit effort="100" lower="-0.34907" upper="1.88496" velocity="100"/>
  </joint>
  <joint name="right_pinky_pip_offset" type="fixed">
    <parent link="right_pinky_pip_jointbody"/>
    <child link="right_pinky_ip"/>
    <origin rpy="0.0 0.0 0.0" xyz="-0.0 -0.0 -0.0"/>
  </joint>
  <link name="right_pinky_fingertip">
    <inertial>
      <origin rpy="0.0 0.0 0.0" xyz="-0.009 0.0 0.035"/>
      <mass value="0.0"/>
      <inertia ixx="0.0" ixy="0" ixz="0" iyy="0.0" iyz="0" izz="0.0"/>
    </inertial>
  </link>
  <joint name="right_pinky_ip2right_index_fingertip_fixed_offset" type="fixed">
    <parent link="right_pinky_ip"/>
    <child link="right_pinky_fingertip"/>
    <origin rpy="0.0 0.0 0.0" xyz="-0.009 0.0 0.035"/>
  </joint>
  <!-- Attach right ORCA hand -->
  <joint name="right_hand_joint" type="fixed">
    <parent link="handconnector_link21_1"/>
    <child link="right_tower"/>
    <origin rpy="0 3.14159 1.5708" xyz="0 0.0407 -0.0797"/>
  </joint>
</robot>
